Traceback (most recent call last):
  File "/Users/kamimura/opt/anaconda3/envs/jupyter-book/lib/python3.9/site-packages/jupyter_cache/executors/utils.py", line 51, in single_nb_execution
    executenb(
  File "/Users/kamimura/opt/anaconda3/envs/jupyter-book/lib/python3.9/site-packages/nbclient/client.py", line 1204, in execute
    return NotebookClient(nb=nb, resources=resources, km=km, **kwargs).execute()
  File "/Users/kamimura/opt/anaconda3/envs/jupyter-book/lib/python3.9/site-packages/nbclient/util.py", line 84, in wrapped
    return just_run(coro(*args, **kwargs))
  File "/Users/kamimura/opt/anaconda3/envs/jupyter-book/lib/python3.9/site-packages/nbclient/util.py", line 62, in just_run
    return loop.run_until_complete(coro)
  File "/Users/kamimura/opt/anaconda3/envs/jupyter-book/lib/python3.9/asyncio/base_events.py", line 647, in run_until_complete
    return future.result()
  File "/Users/kamimura/opt/anaconda3/envs/jupyter-book/lib/python3.9/site-packages/nbclient/client.py", line 663, in async_execute
    await self.async_execute_cell(
  File "/Users/kamimura/opt/anaconda3/envs/jupyter-book/lib/python3.9/site-packages/nbclient/client.py", line 965, in async_execute_cell
    await self._check_raise_for_error(cell, cell_index, exec_reply)
  File "/Users/kamimura/opt/anaconda3/envs/jupyter-book/lib/python3.9/site-packages/nbclient/client.py", line 862, in _check_raise_for_error
    raise CellExecutionError.from_cell_and_msg(cell, exec_reply_content)
nbclient.exceptions.CellExecutionError: An error occurred while executing the following cell:
------------------
X_df = boston_df.drop(['INDEX', 'MEDV'], axis=1)
y_df = boston_df['MEDV']
X_np = X_df.to_numpy()
y_np = y_df.to_numpy()
------------------

[0;31m---------------------------------------------------------------------------[0m
[0;31mNameError[0m                                 Traceback (most recent call last)
Input [0;32mIn [3][0m, in [0;36m<cell line: 1>[0;34m()[0m
[0;32m----> 1[0m X_df [38;5;241m=[39m [43mboston_df[49m[38;5;241m.[39mdrop([[38;5;124m'[39m[38;5;124mINDEX[39m[38;5;124m'[39m, [38;5;124m'[39m[38;5;124mMEDV[39m[38;5;124m'[39m], axis[38;5;241m=[39m[38;5;241m1[39m)
[1;32m      2[0m y_df [38;5;241m=[39m boston_df[[38;5;124m'[39m[38;5;124mMEDV[39m[38;5;124m'[39m]
[1;32m      3[0m X_np [38;5;241m=[39m X_df[38;5;241m.[39mto_numpy()

[0;31mNameError[0m: name 'boston_df' is not defined
NameError: name 'boston_df' is not defined

